<?xml version="1.0"?>
    <robot name="lip01">
        <link name="base"/>
    
        <joint name="body_joint" type="planar">
            <parent link="base"/>
            <child  link="body"/>
        </joint>
        <link name="body">
            <inertial>
                <origin xyz="0 0 0" rpy="0 0 0"/>
                <mass value="0.5"/>
                <inertia ixx="0.0005" ixy="0" ixz="0"
                                iyy="0.0005" iyz="0"
                                izz="0.0005"/>
            </inertial>
            <visual>
                <origin xyz = "0 0 0" rpy="0 0 0"/>
                <geometry>
                    <sphere radius="0.05"/>
                </gometry>
                <material name="red">
                    <color rgba="1.0 0 0"/>
                </mateiral>
            </visual>
            <collision>
                <origin xzy="0 0 0" rpy="0 0 0"/>
                <geometry>
                    <sphere radius="0.05"/>
                </geometry>
            </collision>
        </link>

        <joint name="left_leg_joint" type"revolute">
            <parent link="body"/>
            <child  link="left_leg"/>
        </joint>

        <link name="left_leg">
            <inertial>
                <origin xyz="0 0 0" rpy
            <visual>
                <geometry>
                    <
